<?xml version="1.0" encoding="utf-8"?>
<!-- This URDF was automatically created by SolidWorks to URDF Exporter! Originally created by
Stephen Brawner (brawner@gmail.com) 
     Commit Version: 1.6.0-4-g7f85cfe  Build Version: 1.6.7995.38578
     For more information, please see http://wiki.ros.org/sw_urdf_exporter -->
<robot
  name="robot_urdf">
  <link
    name="base_link">
  </link>
  <link
    name="chassis_link">
    <inertial>
      <origin
        xyz="-0.0025361 -6.9389E-16 -0.1141"
        rpy="0 0 0" />
      <mass
        value="74.085" />
      <inertia
        ixx="40.423"
        ixy="1.5444E-13"
        ixz="-0.053004"
        iyy="43.314"
        iyz="7.2533E-14"
        izz="70.007" />
    </inertial>
    <visual>
      <origin
        xyz="0 0 0"
        rpy="0 0 0" />
      <geometry>
        <mesh
          filename="package://robot_urdf/meshes/2w/chassis_link.STL" />
      </geometry>
      <material
        name="">
        <color
          rgba="0.89804 0.91765 0.92941 1" />
      </material>
    </visual>
    <collision>
      <origin
        xyz="0 0 0"
        rpy="0 0 0" />
      <geometry>
        <mesh
          filename="package://robot_urdf/meshes/2w/chassis_link.STL" />
      </geometry>
    </collision>
  </link>
  <joint
    name="chassis_joint"
    type="fixed">
    <origin
      xyz="0.0112876459450606 -0.015426091141137 0.96832"
      rpy="0 0 0" />
    <parent
      link="base_link" />
    <child
      link="chassis_link" />
    <axis
      xyz="0 0 0" />
  </joint>
  <link
    name="left_wheel_holder_link">
    <inertial>
      <origin
        xyz="2.0817E-16 -2.2204E-16 -0.2296"
        rpy="0 0 0" />
      <mass
        value="4.2419" />
      <inertia
        ixx="0.1287"
        ixy="-1.0555E-16"
        ixz="-1.597E-16"
        iyy="0.13522"
        iyz="4.8616E-17"
        izz="0.079121" />
    </inertial>
    <visual>
      <origin
        xyz="0 0 0"
        rpy="0 0 0" />
      <geometry>
        <mesh
          filename="package://robot_urdf/meshes/2w/left_wheel_holder_link.STL" />
      </geometry>
      <material
        name="">
        <color
          rgba="0.89804 0.91765 0.92941 1" />
      </material>
    </visual>
    <collision>
      <origin
        xyz="0 0 0"
        rpy="0 0 0" />
      <geometry>
        <mesh
          filename="package://robot_urdf/meshes/2w/left_wheel_holder_link.STL" />
      </geometry>
    </collision>
  </link>
  <joint
    name="left_wheel_holder_joint"
    type="fixed">
    <origin
      xyz="-0.0672750000000006 0.7012 -0.42432"
      rpy="0 0 0" />
    <parent
      link="chassis_link" />
    <child
      link="left_wheel_holder_link" />
    <axis
      xyz="0 0 0" />
  </joint>
  <link
    name="left_wheel_link">
    <inertial>
      <origin
        xyz="-6.93889390390723E-18 1.11022302462516E-16 -2.77555756156289E-17"
        rpy="0 0 0" />
      <mass
        value="5.91184905552528" />
      <inertia
        ixx="0.0568562229833385"
        ixy="-6.91191767359212E-18"
        ixz="-4.24872496741667E-34"
        iyy="0.111249175526875"
        iyz="-5.54086297297122E-35"
        izz="0.0568562229833384" />
    </inertial>
    <visual>
      <origin
        xyz="0 0 0"
        rpy="0 0 0" />
      <geometry>
        <mesh
          filename="package://robot_urdf/meshes/2w/left_wheel_link.STL" />
      </geometry>
      <material
        name="">
        <color
          rgba="0.298039215686275 0.298039215686275 0.298039215686275 1" />
      </material>
    </visual>
    <collision>
      <origin
        xyz="0 0 0"
        rpy="0 0 0" />
      <geometry>
        <mesh
          filename="package://robot_urdf/meshes/2w/left_wheel_link.STL" />
      </geometry>
    </collision>
  </link>
  <joint
    name="left_wheel_joint"
    type="continuous">
    <origin
      xyz="0 0 -0.35"
      rpy="0 0 0" />
    <parent
      link="left_wheel_holder_link" />
    <child
      link="left_wheel_link" />
    <axis
      xyz="0 -1 0" />
    <limit
      effort="20"
      velocity="10" />
  </joint>
  <link
    name="right_wheel_holder_link">
    <inertial>
      <origin
        xyz="1.38777878078145E-16 -1.11022302462516E-16 -0.229600737446319"
        rpy="0 0 0" />
      <mass
        value="4.24194552497604" />
      <inertia
        ixx="0.12870471215313"
        ixy="-8.86107503999812E-17"
        ixz="-1.76412809127544E-16"
        iyy="0.135223950425352"
        iyz="-1.17287016832933E-17"
        izz="0.0791209297176007" />
    </inertial>
    <visual>
      <origin
        xyz="0 0 0"
        rpy="0 0 0" />
      <geometry>
        <mesh
          filename="package://robot_urdf/meshes/2w/right_wheel_holder_link.STL" />
      </geometry>
      <material
        name="">
        <color
          rgba="0.898039215686275 0.917647058823529 0.929411764705882 1" />
      </material>
    </visual>
    <collision>
      <origin
        xyz="0 0 0"
        rpy="0 0 0" />
      <geometry>
        <mesh
          filename="package://robot_urdf/meshes/2w/right_wheel_holder_link.STL" />
      </geometry>
    </collision>
  </link>
  <joint
    name="right_wheel_holder_joint"
    type="fixed">
    <origin
      xyz="-0.0672750000000007 -0.7012 -0.42432"
      rpy="0 0 0" />
    <parent
      link="chassis_link" />
    <child
      link="right_wheel_holder_link" />
    <axis
      xyz="0 0 0" />
  </joint>
  <link
    name="right_wheel_link">
    <inertial>
      <origin
        xyz="-6.93889390390723E-18 -1.11022302462516E-16 -2.77555756156289E-17"
        rpy="0 0 0" />
      <mass
        value="5.91184905552528" />
      <inertia
        ixx="0.0568562229833385"
        ixy="-3.21890613138286E-35"
        ixz="-8.41424213201121E-34"
        iyy="0.111249175526875"
        iyz="1.47334202303585E-18"
        izz="0.0568562229833385" />
    </inertial>
    <visual>
      <origin
        xyz="0 0 0"
        rpy="0 0 0" />
      <geometry>
        <mesh
          filename="package://robot_urdf/meshes/2w/right_wheel_link.STL" />
      </geometry>
      <material
        name="">
        <color
          rgba="0.298039215686275 0.298039215686275 0.298039215686275 1" />
      </material>
    </visual>
    <collision>
      <origin
        xyz="0 0 0"
        rpy="0 0 0" />
      <geometry>
        <mesh
          filename="package://robot_urdf/meshes/2w/right_wheel_link.STL" />
      </geometry>
    </collision>
  </link>
  <joint
    name="right_wheel_joint"
    type="continuous">
    <origin
      xyz="0 0 -0.35"
      rpy="0 0 0" />
    <parent
      link="right_wheel_holder_link" />
    <child
      link="right_wheel_link" />
    <axis
      xyz="0 -1 0" />
    <limit
      effort="20"
      velocity="10" />
  </joint>
  <link
    name="depth_camera_link">
  </link>
  <joint
    name="depth_camera_joint"
    type="fixed">
    <origin
      xyz="1.017 0 0"
      rpy="0 0 0" />
    <parent
      link="chassis_link" />
    <child
      link="depth_camera_link" />
    <axis
      xyz="0 0 0" />
  </joint>

  <ros2_control name="IgnitionSystem" type="system">

    <hardware>
      <plugin>ign_ros2_control/IgnitionSystem</plugin>
    </hardware>

    <joint name="left_wheel_joint">
      <command_interface name="velocity" />
      <state_interface name="position" />
      <state_interface name="velocity" />
    </joint>

    <joint name="right_wheel_joint">
      <command_interface name="velocity" />
      <state_interface name="position" />
      <state_interface name="velocity" />
    </joint>

  </ros2_control>

  <gazebo>

    <plugin filename="libign_ros2_control-system.so"
      name="ign_ros2_control::IgnitionROS2ControlPlugin">
      <robot_param>robot_description</robot_param>
      <robot_param_node>robot_state_publisher</robot_param_node>
      <parameters>/home/manfred/Projects/Vitrox/src/robot_urdf/config/diffdrive.yaml</parameters>
    </plugin>

  </gazebo>

  <gazebo reference="left_wheel_link">
    <mu1>1.2</mu1>
    <mu2>1.2</mu2>
    <kp>1000000.0</kp>
    <kd>100.0</kd>
  </gazebo>

  <gazebo reference="right_wheel_link">
    <mu1>1.2</mu1>
    <mu2>1.2</mu2>
    <kp>1000000.0</kp>
    <kd>100.0</kd>
  </gazebo>

  <gazebo reference="chassis_link">
    <material>Gazebo/Orange</material>
    <mu1>0.0</mu1>
    <mu2>0.0</mu2>
  </gazebo>

  <gazebo reference="depth_camera_link">
    <sensor name="rgbd_camera" type="rgbd_camera">
      <ignition_frame_id>Depth_camera_link</ignition_frame_id>
      <camera name="rgbd_camera_frame">
        <horizontal_fov>1.3962634</horizontal_fov>
        <lens>
          <intrinsics>
            <fx>277.1</fx>
            <fy>277.1</fy>
            <cx>160.5</cx>
            <cy>120.5</cy>
            <s>0</s>
          </intrinsics>
        </lens>
        <distortion>
          <k1>0.104207</k1>
          <k2>-0.255558</k2>
          <k3>0.128694</k3>
          <p1>0.000512</p1>
          <p2>0.000319</p2>
          <center>0.5 0.5</center>
        </distortion>
        <image>
          <width>1280</width>
          <height>720</height>
          <format>L8</format>
        </image>
        <clip>
          <near>0.01</near>
          <far>300</far>
        </clip>
        <depth_camera>
          <clip>
            <near>0.1</near>
            <far>10</far>
          </clip>
        </depth_camera>
        <noise>
          <type>gaussian</type>
          <mean>0</mean>
          <stddev>0.003</stddev>
        </noise>
      </camera>
      <always_on>1</always_on>
      <update_rate>10</update_rate>
      <visualize>0</visualize>
      <topic>depth_camera</topic>
    </sensor>
  </gazebo>
</robot>
