<?xml version="1.0" encoding="utf-8"?>
<!-- This URDF was automatically created by SolidWorks to URDF Exporter! Originally created by Stephen Brawner (brawner@gmail.com) 
     Commit Version: 1.6.0-4-g7f85cfe  Build Version: 1.6.7995.38578
     For more information, please see http://wiki.ros.org/sw_urdf_exporter -->
<robot
  name="2wv5">
  <link
    name="base_link">
    <inertial>
      <origin
        xyz="0.06427 -2.6021E-16 0.95062"
        rpy="0 0 0" />
      <mass
        value="62.522" />
      <inertia
        ixx="27.455"
        ixy="-5.3228E-14"
        ixz="-0.071116"
        iyy="29.275"
        iyz="-1.4137E-15"
        izz="51.49" />
    </inertial>
    <visual>
      <origin
        xyz="0 0 0"
        rpy="0 0 0" />
      <geometry>
        <mesh
          filename="package://2wv5/meshes/base_link.STL" />
      </geometry>
      <material
        name="">
        <color
          rgba="0.89804 0.91765 0.92941 1" />
      </material>
    </visual>
    <collision>
      <origin
        xyz="0 0 0"
        rpy="0 0 0" />
      <geometry>
        <mesh
          filename="package://2wv5/meshes/base_link.STL" />
      </geometry>
    </collision>
  </link>
  <link
    name="chassis_link">
    <inertial>
      <origin
        xyz="-0.0030051 -1.8562E-16 -0.017698"
        rpy="0 0 0" />
      <mass
        value="62.522" />
      <inertia
        ixx="27.455"
        ixy="-5.3495E-14"
        ixz="-0.071116"
        iyy="29.275"
        iyz="-1.4035E-15"
        izz="51.49" />
    </inertial>
    <visual>
      <origin
        xyz="0 0 0"
        rpy="0 0 0" />
      <geometry>
        <mesh
          filename="package://2wv5/meshes/chassis_link.STL" />
      </geometry>
      <material
        name="">
        <color
          rgba="0.89804 0.91765 0.92941 1" />
      </material>
    </visual>
    <collision>
      <origin
        xyz="0 0 0"
        rpy="0 0 0" />
      <geometry>
        <mesh
          filename="package://2wv5/meshes/chassis_link.STL" />
      </geometry>
    </collision>
  </link>
  <joint
    name="chassis_joint"
    type="fixed">
    <origin
      xyz="0.067275 0 0.96832"
      rpy="0 0 0" />
    <parent
      link="base_link" />
    <child
      link="chassis_link" />
    <axis
      xyz="0 0 0" />
  </joint>
  <link
    name="left_wheel_holder_link">
    <inertial>
      <origin
        xyz="1.87350135405495E-16 -2.22044604925031E-16 -0.22960073744632"
        rpy="0 0 0" />
      <mass
        value="4.24194552497602" />
      <inertia
        ixx="0.12870471215313"
        ixy="-1.05546231829706E-16"
        ixz="-1.60218871072035E-16"
        iyy="0.135223950425351"
        iyz="4.92528640356397E-17"
        izz="0.0791209297176001" />
    </inertial>
    <visual>
      <origin
        xyz="0 0 0"
        rpy="0 0 0" />
      <geometry>
        <mesh
          filename="package://2wv5/meshes/left_wheel_holder_link.STL" />
      </geometry>
      <material
        name="">
        <color
          rgba="0.898039215686275 0.917647058823529 0.929411764705882 1" />
      </material>
    </visual>
    <collision>
      <origin
        xyz="0 0 0"
        rpy="0 0 0" />
      <geometry>
        <mesh
          filename="package://2wv5/meshes/left_wheel_holder_link.STL" />
      </geometry>
    </collision>
  </link>
  <joint
    name="left_wheel_holder_joint"
    type="fixed">
    <origin
      xyz="-0.067275 0.7012 -0.42432"
      rpy="0 0 0" />
    <parent
      link="chassis_link" />
    <child
      link="left_wheel_holder_link" />
    <axis
      xyz="0 0 0" />
  </joint>
  <link
    name="left_wheel_link">
    <inertial>
      <origin
        xyz="-6.93889390390723E-18 1.11022302462516E-16 -2.77555756156289E-17"
        rpy="0 0 0" />
      <mass
        value="5.91184905552528" />
      <inertia
        ixx="0.0568562229833385"
        ixy="-6.91191767359212E-18"
        ixz="-4.24872496741667E-34"
        iyy="0.111249175526875"
        iyz="-5.54086297297122E-35"
        izz="0.0568562229833384" />
    </inertial>
    <visual>
      <origin
        xyz="0 0 0"
        rpy="0 0 0" />
      <geometry>
        <mesh
          filename="package://2wv5/meshes/left_wheel_link.STL" />
      </geometry>
      <material
        name="">
        <color
          rgba="0.298039215686275 0.298039215686275 0.298039215686275 1" />
      </material>
    </visual>
    <collision>
      <origin
        xyz="0 0 0"
        rpy="0 0 0" />
      <geometry>
        <mesh
          filename="package://2wv5/meshes/left_wheel_link.STL" />
      </geometry>
    </collision>
  </link>
  <joint
    name="left_wheel_joint"
    type="continuous">
    <origin
      xyz="0 0 -0.35"
      rpy="0 0 0" />
    <parent
      link="left_wheel_holder_link" />
    <child
      link="left_wheel_link" />
    <axis
      xyz="0 -1 0" />
    <limit
      effort="100"
      velocity="10" />
  </joint>
  <link
    name="right_wheel_holder_link">
    <inertial>
      <origin
        xyz="1.04083408558608E-16 -1.11022302462516E-16 -0.229600737446319"
        rpy="0 0 0" />
      <mass
        value="4.24194552497604" />
      <inertia
        ixx="0.12870471215313"
        ixy="-8.86107503999811E-17"
        ixz="-1.77922564794508E-16"
        iyy="0.135223950425352"
        iyz="-4.8677348105335E-18"
        izz="0.0791209297176007" />
    </inertial>
    <visual>
      <origin
        xyz="0 0 0"
        rpy="0 0 0" />
      <geometry>
        <mesh
          filename="package://2wv5/meshes/right_wheel_holder_link.STL" />
      </geometry>
      <material
        name="">
        <color
          rgba="0.898039215686275 0.917647058823529 0.929411764705882 1" />
      </material>
    </visual>
    <collision>
      <origin
        xyz="0 0 0"
        rpy="0 0 0" />
      <geometry>
        <mesh
          filename="package://2wv5/meshes/right_wheel_holder_link.STL" />
      </geometry>
    </collision>
  </link>
  <joint
    name="right_wheel_holder_joint"
    type="fixed">
    <origin
      xyz="-0.067275 -0.7012 -0.42432"
      rpy="0 0 0" />
    <parent
      link="chassis_link" />
    <child
      link="right_wheel_holder_link" />
    <axis
      xyz="0 0 0" />
  </joint>
  <link
    name="right_wheel_link">
    <inertial>
      <origin
        xyz="-6.93889390390723E-18 -1.11022302462516E-16 -2.77555756156289E-17"
        rpy="0 0 0" />
      <mass
        value="5.91184905552528" />
      <inertia
        ixx="0.0568562229833385"
        ixy="-3.21890613138286E-35"
        ixz="-8.41424213201121E-34"
        iyy="0.111249175526875"
        iyz="1.47334202303585E-18"
        izz="0.0568562229833385" />
    </inertial>
    <visual>
      <origin
        xyz="0 0 0"
        rpy="0 0 0" />
      <geometry>
        <mesh
          filename="package://2wv5/meshes/right_wheel_link.STL" />
      </geometry>
      <material
        name="">
        <color
          rgba="0.298039215686275 0.298039215686275 0.298039215686275 1" />
      </material>
    </visual>
    <collision>
      <origin
        xyz="0 0 0"
        rpy="0 0 0" />
      <geometry>
        <mesh
          filename="package://2wv5/meshes/right_wheel_link.STL" />
      </geometry>
    </collision>
  </link>
  <joint
    name="right_wheel_joint"
    type="continuous">
    <origin
      xyz="0 0 -0.35"
      rpy="0 0 0" />
    <parent
      link="right_wheel_holder_link" />
    <child
      link="right_wheel_link" />
    <axis
      xyz="0 -1 0" />
    <limit
      effort="100"
      velocity="10" />
  </joint>
  <link
    name="ball_link_fl">
    <inertial>
      <origin
        xyz="0 0 3.46944695195361E-18"
        rpy="0 0 0" />
      <mass
        value="0.204706177307911" />
      <inertia
        ixx="7.36942238308479E-05"
        ixy="0"
        ixz="0"
        iyy="7.36942238308479E-05"
        iyz="0"
        izz="7.36942238308479E-05" />
    </inertial>
    <visual>
      <origin
        xyz="0 0 0"
        rpy="0 0 0" />
      <geometry>
        <mesh
          filename="package://2wv5/meshes/ball_link_fl.STL" />
      </geometry>
      <material
        name="">
        <color
          rgba="1 1 1 1" />
      </material>
    </visual>
    <collision>
      <origin
        xyz="0 0 0"
        rpy="0 0 0" />
      <geometry>
        <mesh
          filename="package://2wv5/meshes/ball_link_fl.STL" />
      </geometry>
    </collision>
  </link>
  <joint
    name="ball_joint_fl"
    type="fixed">
    <origin
      xyz="0.68801 0.6072 -0.93832"
      rpy="0 0 0" />
    <parent
      link="chassis_link" />
    <child
      link="ball_link_fl" />
    <axis
      xyz="0 1 0" />
  </joint>
  <link
    name="ball_link_fr">
    <inertial>
      <origin
        xyz="0 0 3.46944695195361E-18"
        rpy="0 0 0" />
      <mass
        value="0.204706177307911" />
      <inertia
        ixx="7.36942238308479E-05"
        ixy="0"
        ixz="0"
        iyy="7.36942238308479E-05"
        iyz="0"
        izz="7.36942238308479E-05" />
    </inertial>
    <visual>
      <origin
        xyz="0 0 0"
        rpy="0 0 0" />
      <geometry>
        <mesh
          filename="package://2wv5/meshes/ball_link_fr.STL" />
      </geometry>
      <material
        name="">
        <color
          rgba="1 1 1 1" />
      </material>
    </visual>
    <collision>
      <origin
        xyz="0 0 0"
        rpy="0 0 0" />
      <geometry>
        <mesh
          filename="package://2wv5/meshes/ball_link_fr.STL" />
      </geometry>
    </collision>
  </link>
  <joint
    name="ball_joint_fr"
    type="fixed">
    <origin
      xyz="0.68801 -0.6072 -0.93832"
      rpy="0 0 0" />
    <parent
      link="chassis_link" />
    <child
      link="ball_link_fr" />
    <axis
      xyz="0 1 0" />
  </joint>
  <link
    name="ball_link_br">
    <inertial>
      <origin
        xyz="0 -1.11022302462516E-16 -3.46944695195361E-18"
        rpy="0 0 0" />
      <mass
        value="0.204706177307911" />
      <inertia
        ixx="7.36942238308479E-05"
        ixy="0"
        ixz="0"
        iyy="7.36942238308479E-05"
        iyz="0"
        izz="7.36942238308479E-05" />
    </inertial>
    <visual>
      <origin
        xyz="0 0 0"
        rpy="0 0 0" />
      <geometry>
        <mesh
          filename="package://2wv5/meshes/ball_link_br.STL" />
      </geometry>
      <material
        name="">
        <color
          rgba="1 1 1 1" />
      </material>
    </visual>
    <collision>
      <origin
        xyz="0 0 0"
        rpy="0 0 0" />
      <geometry>
        <mesh
          filename="package://2wv5/meshes/ball_link_br.STL" />
      </geometry>
    </collision>
  </link>
  <joint
    name="ball_joint_br"
    type="fixed">
    <origin
      xyz="-0.76256 -0.6072 -0.93832"
      rpy="3.1416 0 3.1416" />
    <parent
      link="chassis_link" />
    <child
      link="ball_link_br" />
    <axis
      xyz="0 1 0" />
  </joint>
  <link
    name="ball_link_bl">
    <inertial>
      <origin
        xyz="0 0 3.46944695195361E-18"
        rpy="0 0 0" />
      <mass
        value="0.204706177307911" />
      <inertia
        ixx="7.3694223830848E-05"
        ixy="-1.87226095231855E-21"
        ixz="2.3979864158557E-21"
        iyy="7.3694223830848E-05"
        iyz="-3.09568679353192E-20"
        izz="7.3694223830848E-05" />
    </inertial>
    <visual>
      <origin
        xyz="0 0 0"
        rpy="0 0 0" />
      <geometry>
        <mesh
          filename="package://2wv5/meshes/ball_link_bl.STL" />
      </geometry>
      <material
        name="">
        <color
          rgba="1 1 1 1" />
      </material>
    </visual>
    <collision>
      <origin
        xyz="0 0 0"
        rpy="0 0 0" />
      <geometry>
        <mesh
          filename="package://2wv5/meshes/ball_link_bl.STL" />
      </geometry>
    </collision>
  </link>
  <joint
    name="ball_joint_bl"
    type="fixed">
    <origin
      xyz="-0.76256 0.6072 -0.93832"
      rpy="0 0 0" />
    <parent
      link="chassis_link" />
    <child
      link="ball_link_bl" />
    <axis
      xyz="0 1 0" />
  </joint>
  <link
    name="depth_link_r">
    <inertial>
      <origin
        xyz="-0.868780689500117 0.698663365335847 0.19875183960793"
        rpy="0 0 0" />
      <mass
        value="62.5218920640007" />
      <inertia
        ixx="27.5773527401811"
        ixy="0.454812120000004"
        ixz="-0.0686928769999475"
        iyy="29.1528681396575"
        iyz="0.018406200917906"
        izz="51.4898850990373" />
    </inertial>
    <visual>
      <origin
        xyz="0 0 0"
        rpy="0 0 0" />
      <geometry>
        <mesh
          filename="package://2wv5/meshes/depth_link_r.STL" />
      </geometry>
      <material
        name="">
        <color
          rgba="0.898039215686275 0.917647058823529 0.929411764705882 1" />
      </material>
    </visual>
    <collision>
      <origin
        xyz="0 0 0"
        rpy="0 0 0" />
      <geometry>
        <mesh
          filename="package://2wv5/meshes/depth_link_r.STL" />
      </geometry>
    </collision>
  </link>
  <joint
    name="depth_joint_r"
    type="fixed">
    <origin
      xyz="1.017 -0.45 -0.21645"
      rpy="0 0 0.2618" />
    <parent
      link="chassis_link" />
    <child
      link="depth_link_r" />
    <axis
      xyz="0 0 0" />
  </joint>
  <link
    name="depth_link_l">
    <inertial>
      <origin
        xyz="-0.868780689500117 -0.698663365335849 0.198751839607931"
        rpy="0 0 0" />
      <mass
        value="62.5218920640007" />
      <inertia
        ixx="27.5773527401811"
        ixy="-0.454812120000093"
        ixz="-0.0686928769999467"
        iyy="29.1528681396575"
        iyz="-0.0184062009179073"
        izz="51.4898850990373" />
    </inertial>
    <visual>
      <origin
        xyz="0 0 0"
        rpy="0 0 0" />
      <geometry>
        <mesh
          filename="package://2wv5/meshes/depth_link_l.STL" />
      </geometry>
      <material
        name="">
        <color
          rgba="0.898039215686275 0.917647058823529 0.929411764705882 1" />
      </material>
    </visual>
    <collision>
      <origin
        xyz="0 0 0"
        rpy="0 0 0" />
      <geometry>
        <mesh
          filename="package://2wv5/meshes/depth_link_l.STL" />
      </geometry>
    </collision>
  </link>
  <joint
    name="depth_joint_l"
    type="fixed">
    <origin
      xyz="1.017 0.45 -0.21645"
      rpy="0 0 -0.2618" />
    <parent
      link="chassis_link" />
    <child
      link="depth_link_l" />
    <axis
      xyz="0 0 0" />
  </joint>
</robot>