<?xml version="1.0" encoding="utf-8"?>
<!-- This URDF was automatically created by SolidWorks to URDF Exporter! Originally created by Stephen Brawner (brawner@gmail.com) 
     Commit Version: 1.6.0-4-g7f85cfe  Build Version: 1.6.7995.38578
     For more information, please see http://wiki.ros.org/sw_urdf_exporter -->
<robot
  name="ranger1s_urdf_3">

  <link name="base_link"/>

  <link
    name="chassis_link">
    <inertial>
      <origin
        xyz="-0.0031009 -2.2204E-16 -0.23122"
        rpy="0 0 0" />
      <mass
        value="20" />
      <inertia
        ixx="4458"
        ixy="7.4577E-15"
        ixz="-12.91"
        iyy="5083.7"
        iyz="-1.1716E-13"
        izz="9008.3" />
    </inertial>
    <visual>
      <origin
        xyz="0 0 0"
        rpy="0 0 0" />
      <geometry>
        <mesh
          filename="package://ranger1s_urdf_3/meshes/chassis_link.STL" />
      </geometry>
      <material
        name="">
        <color
          rgba="0.52941 0.54902 0.54902 1" />
      </material>
    </visual>
    <collision>
      <origin
        xyz="0 0 0"
        rpy="0 0 0" />
      <geometry>
        <mesh
          filename="package://ranger1s_urdf_3/meshes/chassis_link.STL" />
      </geometry>
    </collision>
  </link>

  <joint
    name="chassis_link"
    type="fixed">
    <origin
      xyz="0.65801 0.7012 -0.64077"
      rpy="0 0 0" />
    <parent
      link="base_link" />
    <child
      link="chassis_link" />
    <axis
      xyz="0 0 1" />
    <limit
      lower="0"
      upper="0"
      effort="100"
      velocity="10" />
    <dynamics
      damping="0.1"
      friction="0.1" />
  </joint>

  <link
    name="wheel_holder_link">
    <inertial>
      <origin
        xyz="1.6653E-16 0 -0.19944"
        rpy="0 0 0" />
      <mass
        value="5" />
      <inertia
        ixx="4.7304"
        ixy="6.1062E-16"
        ixz="1.0365E-15"
        iyy="4.794"
        iyz="8.6173E-16"
        izz="2.6221" />
    </inertial>
    <visual>
      <origin
        xyz="0 0 0"
        rpy="0 0 0" />
      <geometry>
        <mesh
          filename="package://ranger1s_urdf_3/meshes/wheel_holder_link.STL" />
      </geometry>
      <material
        name="">
        <color
          rgba="0.52941 0.54902 0.54902 1" />
      </material>
    </visual>
    <collision>
      <origin
        xyz="0 0 0"
        rpy="0 0 0" />
      <geometry>
        <mesh
          filename="package://ranger1s_urdf_3/meshes/wheel_holder_link.STL" />
      </geometry>
    </collision>
  </link>

  <joint
    name="wheel_holder_joint"
    type="revolute">
    <origin
      xyz="0.65801 0.7012 -0.64077"
      rpy="0 0 0" />
    <parent
      link="chassis_link" />
    <child
      link="wheel_holder_link" />
    <axis
      xyz="0 0 1" />
    <limit
      lower="0"
      upper="0"
      effort="100"
      velocity="10" />
    <dynamics
      damping="0.1"
      friction="0.1" />
  </joint>
  <link
    name="wheel_link">
    <inertial>
      <origin
        xyz="-5.5511E-17 0 -0.0485"
        rpy="0 0 0" />
      <mass
        value="1" />
      <inertia
        ixx="0.095548"
        ixy="2.32E-18"
        ixz="0"
        iyy="0.095548"
        iyz="-2.9266E-18"
        izz="0.17656" />
    </inertial>
    <visual>
      <origin
        xyz="0 0 0"
        rpy="0 0 0" />
      <geometry>
        <mesh
          filename="package://ranger1s_urdf_3/meshes/wheel_link.STL" />
      </geometry>
      <material
        name="">
        <color
          rgba="0.29804 0.29804 0.29804 1" />
      </material>
    </visual>
    <collision>
      <origin
        xyz="0 0 0"
        rpy="0 0 0" />
      <geometry>
        <mesh
          filename="package://ranger1s_urdf_3/meshes/wheel_link.STL" />
      </geometry>
    </collision>
  </link>
  <joint
    name="wheel_joint"
    type="continuous">
    <origin
      xyz="0 -0.0485 -0.35"
      rpy="1.5708 0 0" />
    <parent
      link="wheel_holder_link" />
    <child
      link="wheel_link" />
    <axis
      xyz="0 0 -1" />
    <limit
      effort="100"
      velocity="10" />
    <dynamics
      damping="0.1"
      friction="0.1" />
  </joint>
  <link
    name="wheel_holder_link_1">
    <inertial>
      <origin
        xyz="2.2204E-16 -8.8818E-16 -0.19944"
        rpy="0 0 0" />
      <mass
        value="5" />
      <inertia
        ixx="4.7304"
        ixy="5.2736E-16"
        ixz="-1.5668E-16"
        iyy="4.794"
        iyz="1.8087E-16"
        izz="2.6221" />
    </inertial>
    <visual>
      <origin
        xyz="0 0 0"
        rpy="0 0 0" />
      <geometry>
        <mesh
          filename="package://ranger1s_urdf_3/meshes/wheel_holder_link_1.STL" />
      </geometry>
      <material
        name="">
        <color
          rgba="0.52941 0.54902 0.54902 1" />
      </material>
    </visual>
    <collision>
      <origin
        xyz="0 0 0"
        rpy="0 0 0" />
      <geometry>
        <mesh
          filename="package://ranger1s_urdf_3/meshes/wheel_holder_link_1.STL" />
      </geometry>
    </collision>
  </link>
  <joint
    name="wheel_holder_joint_1"
    type="revolute">
    <origin
      xyz="-0.79256 0.7012 -0.64077"
      rpy="0 0 0" />
    <parent
      link="chassis_link" />
    <child
      link="wheel_holder_link_1" />
    <axis
      xyz="0 0 1" />
    <limit
      lower="0"
      upper="0"
      effort="100"
      velocity="10" />
    <dynamics
      damping="0.1"
      friction="0.1" />
  </joint>
  <link
    name="wheel_link_1">
    <inertial>
      <origin
        xyz="2.2204E-16 0 0.0485"
        rpy="0 0 0" />
      <mass
        value="1" />
      <inertia
        ixx="0.095548"
        ixy="-5.9643E-18"
        ixz="-6.9389E-18"
        iyy="0.095548"
        iyz="-2.1632E-19"
        izz="0.17656" />
    </inertial>
    <visual>
      <origin
        xyz="0 0 0"
        rpy="0 0 0" />
      <geometry>
        <mesh
          filename="package://ranger1s_urdf_3/meshes/wheel_link_1.STL" />
      </geometry>
      <material
        name="">
        <color
          rgba="0.29804 0.29804 0.29804 1" />
      </material>
    </visual>
    <collision>
      <origin
        xyz="0 0 0"
        rpy="0 0 0" />
      <geometry>
        <mesh
          filename="package://ranger1s_urdf_3/meshes/wheel_link_1.STL" />
      </geometry>
    </collision>
  </link>
  <joint
    name="wheel_joint_1"
    type="continuous">
    <origin
      xyz="0 0.0485 -0.35"
      rpy="1.5708 0 0" />
    <parent
      link="wheel_holder_link_1" />
    <child
      link="wheel_link_1" />
    <axis
      xyz="0 0 -1" />
    <limit
      effort="100"
      velocity="10" />
    <dynamics
      damping="0.1"
      friction="0.1" />
  </joint>
  <link
    name="wheel_holder_link_2">
    <inertial>
      <origin
        xyz="4.4409E-16 1.1102E-16 -0.19944"
        rpy="0 0 0" />
      <mass
        value="5" />
      <inertia
        ixx="4.7304"
        ixy="2.0817E-16"
        ixz="3.0391E-16"
        iyy="4.794"
        iyz="1.4616E-16"
        izz="2.6221" />
    </inertial>
    <visual>
      <origin
        xyz="0 0 0"
        rpy="0 0 0" />
      <geometry>
        <mesh
          filename="package://ranger1s_urdf_3/meshes/wheel_holder_link_2.STL" />
      </geometry>
      <material
        name="">
        <color
          rgba="0.52941 0.54902 0.54902 1" />
      </material>
    </visual>
    <collision>
      <origin
        xyz="0 0 0"
        rpy="0 0 0" />
      <geometry>
        <mesh
          filename="package://ranger1s_urdf_3/meshes/wheel_holder_link_2.STL" />
      </geometry>
    </collision>
  </link>
  <joint
    name="wheel_holder_joint_2"
    type="revolute">
    <origin
      xyz="-0.79256 -0.7012 -0.64077"
      rpy="0 0 0" />
    <parent
      link="chassis_link" />
    <child
      link="wheel_holder_link_2" />
    <axis
      xyz="0 0 1" />
    <limit
      lower="0"
      upper="0"
      effort="100"
      velocity="10" />
    <dynamics
      damping="0.1"
      friction="0.1" />
  </joint>
  <link
    name="wheel_link_2">
    <inertial>
      <origin
        xyz="0 0 0.0485"
        rpy="0 0 0" />
      <mass
        value="1" />
      <inertia
        ixx="0.095548"
        ixy="-4.024E-18"
        ixz="-9.1073E-18"
        iyy="0.095548"
        iyz="-2.4467E-19"
        izz="0.17656" />
    </inertial>
    <visual>
      <origin
        xyz="0 0 0"
        rpy="0 0 0" />
      <geometry>
        <mesh
          filename="package://ranger1s_urdf_3/meshes/wheel_link_2.STL" />
      </geometry>
      <material
        name="">
        <color
          rgba="0.29804 0.29804 0.29804 1" />
      </material>
    </visual>
    <collision>
      <origin
        xyz="0 0 0"
        rpy="0 0 0" />
      <geometry>
        <mesh
          filename="package://ranger1s_urdf_3/meshes/wheel_link_2.STL" />
      </geometry>
    </collision>
  </link>
  <joint
    name="wheel_joint_2"
    type="continuous">
    <origin
      xyz="0 0.0485 -0.35"
      rpy="1.5708 0 0" />
    <parent
      link="wheel_holder_link_2" />
    <child
      link="wheel_link_2" />
    <axis
      xyz="0 0 -1" />
    <limit
      effort="100"
      velocity="10" />
    <dynamics
      damping="0.1"
      friction="0.1" />
  </joint>
  <link
    name="wheel_holder_link_3">
    <inertial>
      <origin
        xyz="0 1.1102E-16 -0.19944"
        rpy="0 0 0" />
      <mass
        value="5" />
      <inertia
        ixx="4.7304"
        ixy="-1.1102E-16"
        ixz="2.8413E-16"
        iyy="4.794"
        iyz="1.737E-16"
        izz="2.6221" />
    </inertial>
    <visual>
      <origin
        xyz="0 0 0"
        rpy="0 0 0" />
      <geometry>
        <mesh
          filename="package://ranger1s_urdf_3/meshes/wheel_holder_link_3.STL" />
      </geometry>
      <material
        name="">
        <color
          rgba="0.52941 0.54902 0.54902 1" />
      </material>
    </visual>
    <collision>
      <origin
        xyz="0 0 0"
        rpy="0 0 0" />
      <geometry>
        <mesh
          filename="package://ranger1s_urdf_3/meshes/wheel_holder_link_3.STL" />
      </geometry>
    </collision>
  </link>
  <joint
    name="wheel_holder_joint_3"
    type="revolute">
    <origin
      xyz="0.65801 -0.7012 -0.64077"
      rpy="0 0 0" />
    <parent
      link="chassis_link" />
    <child
      link="wheel_holder_link_3" />
    <axis
      xyz="0 0 1" />
    <limit
      lower="0"
      upper="0"
      effort="100"
      velocity="10" />
    <dynamics
      damping="0.1"
      friction="0.1" />
  </joint>
  <link
    name="wheel_link_3">
    <inertial>
      <origin
        xyz="0 5.5511E-17 -0.0485"
        rpy="0 0 0" />
      <mass
        value="1" />
      <inertia
        ixx="0.095548"
        ixy="8.8194E-19"
        ixz="-6.9389E-18"
        iyy="0.095548"
        iyz="4.4E-19"
        izz="0.17656" />
    </inertial>
    <visual>
      <origin
        xyz="0 0 0"
        rpy="0 0 0" />
      <geometry>
        <mesh
          filename="package://ranger1s_urdf_3/meshes/wheel_link_3.STL" />
      </geometry>
      <material
        name="">
        <color
          rgba="0.29804 0.29804 0.29804 1" />
      </material>
    </visual>
    <collision>
      <origin
        xyz="0 0 0"
        rpy="0 0 0" />
      <geometry>
        <mesh
          filename="package://ranger1s_urdf_3/meshes/wheel_link_3.STL" />
      </geometry>
    </collision>
  </link>
  <joint
    name="wheel_joint_3"
    type="continuous">
    <origin
      xyz="0 -0.0485 -0.35"
      rpy="1.5708 0 0" />
    <parent
      link="wheel_holder_link_3" />
    <child
      link="wheel_link_3" />
    <axis
      xyz="0 0 -1" />
    <limit
      effort="100"
      velocity="10" />
    <dynamics
      damping="0.1"
      friction="0.1" />
  </joint>
  <link
    name="Depth_camera_link">
    <inertial>
      <origin
        xyz="0.01245 0.001112 -2.7835E-05"
        rpy="0 0 0" />
      <mass
        value="1.2669" />
      <inertia
        ixx="0.00076373"
        ixy="1.1341E-05"
        ixz="2.0556E-07"
        iyy="0.00011453"
        iyz="-4.0558E-08"
        izz="0.0007716" />
    </inertial>
    <visual>
      <origin
        xyz="0 0 0"
        rpy="0 0 0" />
      <geometry>
        <mesh
          filename="package://ranger1s_urdf_3/meshes/Depth_camera_link.STL" />
      </geometry>
      <material
        name="">
        <color
          rgba="0.79216 0.81961 0.93333 1" />
      </material>
    </visual>
    <collision>
      <origin
        xyz="0 0 0"
        rpy="0 0 0" />
      <geometry>
        <mesh
          filename="package://ranger1s_urdf_3/meshes/Depth_camera_link.STL" />
      </geometry>
    </collision>
  </link>
  <joint
    name="Depth_camera_joint"
    type="fixed">
    <origin
      xyz="1.017 0 -0.21645"
      rpy="0 0 0" />
    <parent
      link="chassis_link" />
    <child
      link="Depth_camera_link" />
    <axis
      xyz="0 0 0" />
  </joint>
</robot>