<?xml version="1.0" encoding="utf-8"?>
<!-- This URDF was automatically created by SolidWorks to URDF Exporter! Originally created by
Stephen Brawner (brawner@gmail.com) 
     Commit Version: 1.6.0-4-g7f85cfe  Build Version: 1.6.7995.38578
     For more information, please see http://wiki.ros.org/sw_urdf_exporter -->
<robot
  name="robot_urdf">
  <link
    name="base_link">

  </link>
  <link
    name="chassis_link">
    <inertial>
      <origin
        xyz="-0.0057618 8.8769E-15 -0.033998"
        rpy="0 0 0" />
      <mass
        value="32.713" />
      <inertia
        ixx="14.677"
        ixy="-1.0477E-13"
        ixz="-0.068414"
        iyy="16.371"
        iyz="-1.4749E-14"
        izz="28.033" />
    </inertial>
    <visual>
      <origin
        xyz="0 0 0"
        rpy="0 0 0" />
      <geometry>
        <mesh
          filename="package://robot_urdf/meshes/chassis_link.STL" />
      </geometry>
      <material
        name="">
        <color
          rgba="0.89804 0.91765 0.92941 1" />
      </material>
    </visual>
    <collision>
      <origin
        xyz="0 0 0"
        rpy="0 0 0" />
      <geometry>
        <mesh
          filename="package://robot_urdf/meshes/chassis_link.STL" />
      </geometry>
    </collision>
  </link>
  <joint
    name="chassis_joint"
    type="fixed">
    <origin
      xyz="0 0 0.96832"
      rpy="0 0 0" />
    <parent
      link="base_link" />
    <child
      link="chassis_link" />
    <axis
      xyz="0 0 0" />
    <limit
      lower="0"
      upper="0"
      effort="100"
      velocity="10" />
    <dynamics
      damping="0.1"
      friction="0.1" />
  </joint>
  <link
    name="wheel_holder_link_lf">
    <inertial>
      <origin
        xyz="1.1102E-16 -2.2204E-16 -0.2296"
        rpy="0 0 0" />
      <mass
        value="4.2419" />
      <inertia
        ixx="0.1287"
        ixy="-7.3591E-17"
        ixz="-7.8137E-18"
        iyy="0.13522"
        iyz="1.4281E-16"
        izz="0.079121" />
    </inertial>
    <visual>
      <origin
        xyz="0 0 0"
        rpy="0 0 0" />
      <geometry>
        <mesh
          filename="package://robot_urdf/meshes/wheel_holder_link_lf.STL" />
      </geometry>
      <material
        name="">
        <color
          rgba="0.89804 0.91765 0.92941 1" />
      </material>
    </visual>
    <collision>
      <origin
        xyz="0 0 0"
        rpy="0 0 0" />
      <geometry>
        <mesh
          filename="package://robot_urdf/meshes/wheel_holder_link_lf.STL" />
      </geometry>
    </collision>
  </link>
  <joint
    name="wheel_holder_joint_lf"
    type="revolute">
    <origin
      xyz="0.65801 0.7012 -0.42432"
      rpy="0 0 0" />
    <parent
      link="chassis_link" />
    <child
      link="wheel_holder_link_lf" />
    <axis
      xyz="0 0 1" />
    <limit
      lower="0"
      upper="0"
      effort="100"
      velocity="10" />
    <dynamics
      damping="0.1"
      friction="0.1" />
  </joint>
  <link
    name="wheel_link_lf">
    <inertial>
      <origin
        xyz="0 -1.1102E-16 0"
        rpy="0 0 0" />
      <mass
        value="5.9118" />
      <inertia
        ixx="0.056856"
        ixy="3.4492E-18"
        ixz="-1.0892E-32"
        iyy="0.11125"
        iyz="9.227E-19"
        izz="0.056856" />
    </inertial>
    <visual>
      <origin
        xyz="0 0 0"
        rpy="0 0 0" />
      <geometry>
        <cylinder radius="0.194" length="0.05" />
      </geometry>
      <material
        name="">
        <color
          rgba="0.29804 0.29804 0.29804 1" />
      </material>
    </visual>
    <collision>
      <origin
        xyz="0 0 0"
        rpy="0 0 0" />
      <geometry>
        <cylinder radius="0.194" length="0.05" />
      </geometry>
    </collision>
  </link>
  <joint
    name="wheel_joint_lf"
    type="continuous">
    <origin
      xyz="0 0 -0.35"
      rpy="0 0 0" />
    <parent
      link="wheel_holder_link_lf" />
    <child
      link="wheel_link_lf" />
    <axis
      xyz="0 -1 0" />
    <limit
      effort="100"
      velocity="10" />
  </joint>
  <link
    name="wheel_holder_link_lb">
    <inertial>
      <origin
        xyz="1.1102E-16 -1.1102E-16 -0.2296"
        rpy="0 0 0" />
      <mass
        value="4.2419" />
      <inertia
        ixx="0.1287"
        ixy="-3.4869E-17"
        ixz="-6.2384E-17"
        iyy="0.13522"
        iyz="2.0849E-16"
        izz="0.079121" />
    </inertial>
    <visual>
      <origin
        xyz="0 0 0"
        rpy="0 0 0" />
      <geometry>
        <mesh
          filename="package://robot_urdf/meshes/wheel_holder_link_lb.STL" />
      </geometry>
      <material
        name="">
        <color
          rgba="0.89804 0.91765 0.92941 1" />
      </material>
    </visual>
    <collision>
      <origin
        xyz="0 0 0"
        rpy="0 0 0" />
      <geometry>
        <mesh
          filename="package://robot_urdf/meshes/wheel_holder_link_lb.STL" />
      </geometry>
    </collision>
  </link>
  <joint
    name="wheel_holder_joint_lb"
    type="revolute">
    <origin
      xyz="-0.79256 0.7012 -0.42432"
      rpy="0 0 0" />
    <parent
      link="chassis_link" />
    <child
      link="wheel_holder_link_lb" />
    <axis
      xyz="0 0 1" />
    <limit
      lower="0"
      upper="0"
      effort="100"
      velocity="10" />
  </joint>
  <link
    name="wheel_link_lb">
    <inertial>
      <origin
        xyz="0 -1.1102E-16 0"
        rpy="0 0 0" />
      <mass
        value="5.9118" />
      <inertia
        ixx="0.056856"
        ixy="3.4492E-18"
        ixz="-1.0892E-32"
        iyy="0.11125"
        iyz="9.227E-19"
        izz="0.056856" />
    </inertial>
    <visual>
      <origin
        xyz="0 0 0"
        rpy="0 0 0" />
      <geometry>
        <cylinder radius="0.194" length="0.05" />
      </geometry>
      <material
        name="">
        <color
          rgba="0.29804 0.29804 0.29804 1" />
      </material>
    </visual>
    <collision>
      <origin
        xyz="0 0 0"
        rpy="0 0 0" />
      <geometry>
        <cylinder radius="0.194" length="0.05" />
      </geometry>
    </collision>
  </link>
  <joint
    name="wheel_joint_lb"
    type="continuous">
    <origin
      xyz="0 0 -0.35"
      rpy="0 0 0" />
    <parent
      link="wheel_holder_link_lb" />
    <child
      link="wheel_link_lb" />
    <axis
      xyz="0 -1 0" />
    <limit
      effort="100"
      velocity="10" />
  </joint>
  <link
    name="wheel_holder_link_rb">
    <inertial>
      <origin
        xyz="3.3307E-16 -2.2204E-16 -0.2296"
        rpy="0 0 0" />
      <mass
        value="4.2419" />
      <inertia
        ixx="0.1287"
        ixy="-1.1733E-16"
        ixz="-2.6966E-16"
        iyy="0.13522"
        iyz="1.0014E-16"
        izz="0.079121" />
    </inertial>
    <visual>
      <origin
        xyz="0 0 0"
        rpy="0 0 0" />
      <geometry>
        <mesh
          filename="package://robot_urdf/meshes/wheel_holder_link_rb.STL" />
      </geometry>
      <material
        name="">
        <color
          rgba="0.89804 0.91765 0.92941 1" />
      </material>
    </visual>
    <collision>
      <origin
        xyz="0 0 0"
        rpy="0 0 0" />
      <geometry>
        <mesh
          filename="package://robot_urdf/meshes/wheel_holder_link_rb.STL" />
      </geometry>
    </collision>
  </link>
  <joint
    name="wheel_holder_joint_rb"
    type="revolute">
    <origin
      xyz="-0.79256 -0.7012 -0.42432"
      rpy="0 0 0" />
    <parent
      link="chassis_link" />
    <child
      link="wheel_holder_link_rb" />
    <axis
      xyz="0 0 1" />
    <limit
      lower="0"
      upper="0"
      effort="100"
      velocity="10" />
  </joint>
  <link
    name="wheel_link_rb">
    <inertial>
      <origin
        xyz="0 -1.1102E-16 0"
        rpy="0 0 0" />
      <mass
        value="5.9118" />
      <inertia
        ixx="0.056856"
        ixy="3.4492E-18"
        ixz="-1.0892E-32"
        iyy="0.11125"
        iyz="9.227E-19"
        izz="0.056856" />
    </inertial>
    <visual>
      <origin
        xyz="0 0 0"
        rpy="0 0 0" />
      <geometry>
        <cylinder radius="0.194" length="0.05" />
      </geometry>
      <material
        name="">
        <color
          rgba="0.29804 0.29804 0.29804 1" />
      </material>
    </visual>
    <collision>
      <origin
        xyz="0 0 0"
        rpy="0 0 0" />
      <geometry>
        <cylinder radius="0.194" length="0.05" />
      </geometry>
    </collision>
  </link>
  <joint
    name="wheel_joint_rb"
    type="continuous">
    <origin
      xyz="0 0 -0.35"
      rpy="0 0 0" />
    <parent
      link="wheel_holder_link_rb" />
    <child
      link="wheel_link_rb" />
    <axis
      xyz="0 -1 0" />
    <limit
      effort="100"
      velocity="10" />
  </joint>
  <link
    name="wheel_holder_link_rf">
    <inertial>
      <origin
        xyz="0 -2.2204E-16 -0.2296"
        rpy="0 0 0" />
      <mass
        value="4.2419" />
      <inertia
        ixx="0.1287"
        ixy="-7.3591E-17"
        ixz="-7.9202E-18"
        iyy="0.13522"
        iyz="1.4433E-16"
        izz="0.079121" />
    </inertial>
    <visual>
      <origin
        xyz="0 0 0"
        rpy="0 0 0" />
      <geometry>
        <mesh
          filename="package://robot_urdf/meshes/wheel_holder_link_rf.STL" />
      </geometry>
      <material
        name="">
        <color
          rgba="0.89804 0.91765 0.92941 1" />
      </material>
    </visual>
    <collision>
      <origin
        xyz="0 0 0"
        rpy="0 0 0" />
      <geometry>
        <mesh
          filename="package://robot_urdf/meshes/wheel_holder_link_rf.STL" />
      </geometry>
    </collision>
  </link>
  <joint
    name="wheel_holder_joint_rf"
    type="revolute">
    <origin
      xyz="0.65801 -0.7012 -0.42432"
      rpy="0 0 0" />
    <parent
      link="chassis_link" />
    <child
      link="wheel_holder_link_rf" />
    <axis
      xyz="0 0 1" />
    <limit
      lower="0"
      upper="0"
      effort="100"
      velocity="10" />
  </joint>
  <link
    name="wheel_link_rf">
    <inertial>
      <origin
        xyz="0 -1.1102E-16 0"
        rpy="0 0 0" />
      <mass
        value="5.9118" />
      <inertia
        ixx="0.056856"
        ixy="3.4492E-18"
        ixz="-1.0892E-32"
        iyy="0.11125"
        iyz="9.227E-19"
        izz="0.056856" />
    </inertial>
    <visual>
      <origin
        xyz="0 0 0"
        rpy="0 0 0" />
      <geometry>
        <cylinder radius="0.194" length="0.05" />
      </geometry>
      <material
        name="">
        <color
          rgba="0.29804 0.29804 0.29804 1" />
      </material>
    </visual>
    <collision>
      <origin
        xyz="0 0 0"
        rpy="0 0 0" />
      <geometry>
        <cylinder radius="0.194" length="0.05" />
      </geometry>
    </collision>
  </link>
  <joint
    name="wheel_joint_rf"
    type="continuous">
    <origin
      xyz="0 0 -0.35"
      rpy="0 0 0" />
    <parent
      link="wheel_holder_link_rf" />
    <child
      link="wheel_link_rf" />
    <axis
      xyz="0 -1 0" />
    <limit
      effort="100"
      velocity="10" />
  </joint>
  <link
    name="depth_camera_link">

  </link>
  <joint
    name="depth_camera_joint"
    type="fixed">
    <origin
      xyz="1.017 0 -0.21645"
      rpy="0 0 0" />
    <parent
      link="chassis_link" />
    <child
      link="depth_camera_link" />
    <axis
      xyz="0 0 0" />
  </joint>

  <ros2_control name="IgnitionSystem" type="system">

    <hardware>
      <plugin>ign_ros2_control/IgnitionSystem</plugin>
    </hardware>

    <joint name="wheel_joint_lf">
      <command_interface name="velocity" />
      <state_interface name="position" />
      <state_interface name="velocity" />
    </joint>

    <joint name="wheel_joint_lb">
      <command_interface name="velocity" />
      <state_interface name="position" />
      <state_interface name="velocity" />
    </joint>

    <joint name="wheel_joint_rb">
      <command_interface name="velocity" />
      <state_interface name="position" />
      <state_interface name="velocity" />
    </joint>

    <joint name="wheel_joint_rf">
      <command_interface name="velocity" />
      <state_interface name="position" />
      <state_interface name="velocity" />
    </joint>

    <!-- <joint name="wheel_holder_joint_1"> -->
    <!--   <state_interface name="position" /> -->
    <!--   <state_interface name="velocity" /> -->
    <!-- </joint> -->
    <!---->
    <!-- <joint name="wheel_holder_joint_2"> -->
    <!--   <state_interface name="position" /> -->
    <!--   <state_interface name="velocity" /> -->
    <!-- </joint> -->

  </ros2_control>

  <gazebo>

    <plugin filename="libign_ros2_control-system.so"
      name="ign_ros2_control::IgnitionROS2ControlPlugin">
      <robot_param>robot_description</robot_param>
      <robot_param_node>robot_state_publisher</robot_param_node>
      <parameters>$(find robot_urdf)/config/diffdrive_4w.yaml</parameters>
    </plugin>

  </gazebo>

  <gazebo reference="wheel_link_lf">
    <mu1>1.2</mu1>
    <mu2>0.01</mu2>
    <kp>1000000.0</kp>
    <kd>100.0</kd>
  </gazebo>

  <gazebo reference="wheel_link_lb">
    <mu1>1.2</mu1>
    <mu2>0.01</mu2>
    <kp>1000000.0</kp>
    <kd>100.0</kd>
  </gazebo>

  <gazebo reference="wheel_link_rb">
    <mu1>1.2</mu1>
    <mu2>0.01</mu2>
    <kp>1000000.0</kp>
    <kd>100.0</kd>
  </gazebo>

  <gazebo reference="wheel_link_rf">
    <mu1>1.2</mu1>
    <mu2>0.01</mu2>
    <kp>1000000.0</kp>
    <kd>100.0</kd>
  </gazebo>

  <gazebo reference="chassis_link">
    <material>Gazebo/Orange</material>
  </gazebo>

  <gazebo reference="depth_camera_link">
    <sensor name="rgbd_camera" type="rgbd_camera">
      <ignition_frame_id>depth_camera_link</ignition_frame_id>
      <camera name="rgbd_camera_frame">
        <horizontal_fov>1.3962634</horizontal_fov>
        <lens>
          <intrinsics>
            <fx>277.1</fx>
            <fy>277.1</fy>
            <cx>160.5</cx>
            <cy>120.5</cy>
            <s>0</s>
          </intrinsics>
        </lens>
        <distortion>
          <k1>0.104207</k1>
          <k2>-0.255558</k2>
          <k3>0.128694</k3>
          <p1>0.000512</p1>
          <p2>0.000319</p2>
          <center>0.5 0.5</center>
        </distortion>
        <image>
          <width>1280</width>
          <height>720</height>
          <format>L8</format>
        </image>
        <clip>
          <near>0.01</near>
          <far>300</far>
        </clip>
        <depth_camera>
          <clip>
            <near>0.1</near>
            <far>10</far>
          </clip>
        </depth_camera>
        <noise>
          <type>gaussian</type>
          <mean>0</mean>
          <stddev>0.003</stddev>
        </noise>
      </camera>
      <always_on>1</always_on>
      <update_rate>10</update_rate>
      <visualize>0</visualize>
      <topic>depth_camera</topic>
    </sensor>
  </gazebo>
</robot>
